File: data/springs_database_North_America_Grant_Ferguson_mod.csv
Name,"Discharge (L/s)",Temperature,"Air Temperature","Delta T",Precip,Source,State,"Log Discharge",Latitude,Longitude,"Approx Heat Flow (W)","Corrected Heat Flow","Log approx heat flow","Crustal Heat Flow (mW/m2)","Heat Flow Area (m2)","Heat Flow Area (km2)","Precip Area (m2)",hfa/pa
"Twin Lakes",4.5,21,5.4,15.6,2187,"Motyka et al 1983",Alaska,0.65321251377534,56.7,-132.28,207108,293716.8,5.31619687479279,66.3,4430117.64705882,4.43011764705882,64888.8888888889,68.2723609991942
"Barnes Lake",0.5,26,4.1,21.9,1961,"Motyka et al 1983",Alaska,-0.30102999566398,56.68,-131.88,33472,45814.8,4.52468166285116,66.3,691022.624434389,0.69102262443439,8040.79551249363,85.9395843807608
"Little Melozitna",22,39,0,39,415,"Motyka et al 1983",Alaska,1.34242268082221,65.44,-153.31,2669392,3589872,6.42641235458038,84.1,42685755.0535077,42.6857550535077,1671787.95180723,25.5329959803597
"Akun Strait",0.66666666666667,43,0,43,,"Motyka et al 1983",Alaska,-0.17609125905568,54.14,-165.64,92048,119941.333333333,4.96401435668142,64.3,1865339.55417315,1.86533955417315,#DIV/0!,#DIV/0!
"Upper Ray River",11,44,0,44,349,"Motyka et al 1983",Alaska,1.04139268515823,65.96,-150.92,1564816,2025056,6.1944632780597,98.9,20475793.7310415,20.4757937310415,993971.346704871,20.5999838918104
"Egg Island",3.33333333333333,51,3.5,47.5,955,"Motyka et al 1983",Alaska,0.52287874528034,54.94,-162.91,571813.333333333,662466.666666667,5.75725427785929,71.9,9213722.7630969,9.21372276309689,110073.298429319,83.7053390292764
Chuilnuk,9.16666666666667,51,0,51,526,"Motyka et al 1983",Alaska,0.9622114391106,61.36,-157.75,1572486.66666667,1956020,6.19658697168955,81,24148395.0617284,24.1483950617284,549581.74904943,43.9395869740872
"Lava Creek",6,53,0,53,401,"Motyka et al 1983",Alaska,0.77815125038364,65.23,-162.89,1079472,1330512,6.03321138182245,62.8,21186496.8152866,21.1864968152866,471860.349127182,44.8999303596416
"Reed River",2.66666666666667,57,0,57,326,"Motyka et al 1983",Alaska,0.42596873227228,67.27,-155.11,524394.666666667,635968,5.71965826606722,69.3,9177027.41702742,9.17702741702742,257963.190184049,35.5749493192416
Manley,23.6666666666667,59,0,59,384,"Motyka et al 1983",Alaska,1.37413709399941,65.01,-150.63,4852045.33333333,5842258.66666667,6.68592484988714,98.9,59072382.8783283,59.0723828783283,1943625,30.3928910557995
"Emmons Lake",10,65,2.7,62.3,945,"Motyka et al 1983",Alaska,1,55.33,-162.14,2301200,2606632,6.36195436535346,75,34755093.3333333,34.7550933333333,333714.285714286,104.146255707763
Kanuti,1.5,66,0,66,338,"Motyka et al 1983",Alaska,0.17609125905568,66.34,-150.85,351456,414216,5.5458709619211,95.8,4323757.82881002,4.32375782881002,139952.662721893,30.8944306218879
"Upper Division",13.6666666666667,68,0,68,309,"Motyka et al 1983",Alaska,1.13566260200007,66.34,-156.77,3316517.33333333,3888330.66666667,6.52068227142223,74.8,51983030.3030303,51.9830303030303,1394796.11650485,37.2692680226927
"Partov Cove",3.33333333333333,84,4.8,79.2,958,"Motyka et al 1983",Alaska,0.52287874528034,53.23,-168.31,1032053.33333333,1104576,6.01370214087053,,,,109728.60125261,0
"Hot Springs Cove",3,94,4.8,89.2,958,"Motyka et al 1983",Alaska,0.47712125471966,53.24,-168.36,1054368,1119638.4,6.02299221664076,,,,98755.7411273487,0
"Phillips Soda Springs",0.63333333333333,24,14,10,807,"Youngs 1994",California,-0.19836765376683,38.5217,-122.2608,37098.1333333333,26498.6666666667,4.56935205777062,81.7,324341.085271318,0.32434108527132,24749.4423791822,13.1049855710743
"Red Eye Spring",0.13333333333333,24,13.6,10.4,900,"Youngs 1994",California,-0.8750612633917,39.351,-122.6705,7810.13333333333,5801.81333333333,3.89265844814576,88.3,65705.7002642507,0.06570570026425,4672,14.0637200908071
"England Springs",0.5,24,12.7,11.3,1221,"Youngs 1994",California,-0.30102999566398,38.8967,-122.8817,29288,23639.6,4.46668971587347,81.7,289346.389228886,0.28934638922889,12914.0049140049,22.4056279330587
"Carlsbad Spring",0.2,26,13.3,12.7,1151,"Youngs 1994",California,-0.69897000433602,38.918,-122.7978,13388.8,10627.36,4.12674165417912,81.7,130077.845777234,0.13007784577723,5479.75673327541,23.7378869370872
"Warm Spring",0.35,21,6.7,14.3,374,"Youngs 1994",California,-0.45593195564972,41.1625,-120.4038,16108.4,20940.92,4.20705240536772,32.8,638442.682926829,0.63844268292683,29512.2994652406,21.6331053321949
"Unnamed Spring",0.01666666666667,27,11.9,15.1,351,"Youngs 1994",California,-1.77815125038364,35.94,-117.9025,1185.46666666667,1052.97333333333,3.07388934685385,64.7,16274.703760948,0.01627470376095,1497.4358974359,10.8683809362495
"Hog Hollow Spring",0.13333333333333,30,14,16,1085,"Youngs 1994",California,-0.8750612633917,39.0233,-122.5917,11157.3333333333,8925.86666666667,4.0475604081315,81.7,109251.733986128,0.10925173398613,3875.39170506912,28.1911461603284
"Meyers Warm Spring",0.25,24,7,17,1233,"Youngs 1994",California,-0.60205999132796,38.85,-120.025,14644,17782,4.16565972020949,65,273569.230769231,0.27356923076923,6394.16058394161,42.7842290129961
"Mark West Springs",0.01666666666667,31,13.1,17.9,996,"Youngs 1994",California,-1.77815125038364,38.5488,-122.72,1464.4,1248.22666666667,3.16565972020949,81.7,15278.1721746226,0.01527817217462,527.710843373494,28.9517874541935
"Aetna Springs",0.66666666666667,33,13.9,19.1,887,"Youngs 1994",California,-0.17609125905568,38.6522,-122.4833,64154.6666666667,53276.2666666667,4.80722825282113,81.7,652096.287229702,0.6520962872297,23702.3675310034,27.5118629553247
"Santa Ysabel Springs",3.16666666666667,33,13.5,19.5,475,"Youngs 1994",California,0.50060235056919,35.5822,-120.6645,304734.666666667,258362,5.483921862446,73.7,3505590.23066486,3.50559023066486,210240,16.674230549205
"Unnamed Spring",0.5,28,7.8,20.2,1131,"Youngs 1994",California,-0.30102999566398,40.4425,-121.4125,37656,42258.4,4.57583418529854,87.9,480755.403868032,0.48075540386803,13941.6445623342,34.4834070126043
"Unnamed Spring",0.63333333333333,27,6,21,463,"Youngs 1994",California,-0.19836765376683,41.5417,-120.5667,45047.7333333333,55647.2,4.65367294347066,32.8,1696560.97560976,1.69656097560976,43137.7969762419,39.328873853807
"Boron Spring",1.58333333333333,22,0,22,,"Youngs 1994",California,0.1995723549052,34.4228,-119.538,79496,145742.666666667,4.90034527681205,77.4,1882980.18949182,1.88298018949182,#DIV/0!,#DIV/0!
"Jacumba Hot Springs",0.95,38,15.1,22.9,382,"Youngs 1994",California,-0.02227639471115,32.6158,-116.1922,111294.4,91022.92,5.04647331249028,91.9,990456.147986942,0.99045614798694,78427.2251308901,12.6289837022021
"High Rock Spring",33.0666666666667,30,6.1,23.9,529,"Youngs 1994",California,1.51939041743452,40.2467,-120.0068,2767018.66666667,3306587.30666667,6.44201208895772,58.9,56139003.5087719,56.1390035087719,1971248.39319471,28.4789089505814
"Bare Ranch Spring",0.31666666666667,32,6.9,25.1,332,"Youngs 1994",California,-0.49939764943081,41.1667,-120.0333,29148.5333333333,33255.8266666667,4.46461670725061,32.8,1013897.15447154,1.01389715447154,30079.5180722892,33.7072273576617
"El Encino Springs",0.28333333333333,26,0,26,,"Youngs 1994",California,-0.54770232900537,34.1592,-118.4988,18967.4666666667,30822.1333333333,4.27800932950977,77,400287.445887446,0.40028744588745,#DIV/0!,#DIV/0!
"California Hot Springs",8.33333333333333,45,18.1,26.9,273,"Youngs 1994",California,0.92081875395238,35.8795,-118.677,1220333.33333333,937913.333333333,6.08647847416187,87.2,10755886.8501529,10.7558868501529,962637.362637363,11.1733527781269
"Warm Sps. at Twain",0.31666666666667,38,10,28,1198,"Youngs 1994",California,-0.49939764943081,40.0187,-121.0358,37098.1333333333,37098.1333333333,4.56935205777062,87.9,422049.298445203,0.4220492984452,8335.89315525876,50.6303632477522
"Stinking Springs",0.95,38,9.6,28.4,1250,"Youngs 1994",California,-0.02227639471115,40.2228,-122.7495,111294.4,112884.32,5.04647331249028,88.3,1278418.1200453,1.2784181200453,23967.36,53.3399640196208
"De Luz Warm Springs",0.31666666666667,29,0,29,,"Youngs 1994",California,-0.49939764943081,33.4358,-117.325,25173.7333333333,38423.0666666667,4.40094762738123,107.9,356098.856966327,0.35609885696633,#DIV/0!,#DIV/0!
"Paraiso Springs",0.95,43,11.6,31.4,691,"Youngs 1994",California,-0.02227639471115,36.3313,-121.3675,131168.4,124808.72,5.11782922102595,75.3,1657486.32138114,1.65748632138114,43356.2952243126,38.2294269564731
"Rocky Point Springs",0.13333333333333,32,0,32,,"Youngs 1994",California,-0.8750612633917,37.8858,-122.6287,12273.0666666667,17851.7333333333,4.08895309328972,79.3,225116.435477091,0.22511643547709,#DIV/0!,#DIV/0!
"San Juan Hot Springs",0.95,49,16.3,32.7,294,"Youngs 1994",California,-0.02227639471115,33.589,-117.5003,155017.2,129975.96,5.19037988817457,107.9,1204596.47822057,1.20459647822057,101902.040816327,11.821122212771
"Leonards Hot Sps. (West)",3.33333333333333,41,7.7,33.3,376,"Youngs 1994",California,0.52287874528034,41.5987,-120.0913,432346.666666667,464424,5.63583211497383,32.8,14159268.2926829,14.1592682926829,279574.468085106,50.645784608531
"Harbin Springs",0.5,48,13.9,34.1,1130,"Youngs 1994",California,-0.30102999566398,38.7887,-122.6563,79496,71337.2,4.90034527681205,81.7,873160.342717258,0.87316034271726,13953.982300885,62.5742762094433
"Unnamed Spring",2.5,41,5.1,35.9,662,"Youngs 1994",California,0.39794000867204,37.6433,-118.7575,324260,375514,5.51089337836553,81.8,4590635.69682152,4.59063569682152,119093.655589124,38.5464336795515
"Unnamed Spring",0.31666666666667,49,12.7,36.3,1221,"Youngs 1994",California,-0.49939764943081,38.7767,-122.7625,51672.4,48095.08,4.7132586334549,81.7,588679.069767442,0.58867906976744,8178.86977886978,71.975601236286
"The Hot Springs",1.66666666666667,40,2.8,37.2,729,"Youngs 1994",California,0.22184874961636,38.2242,-119.2145,209200,259408,5.32056168019524,54.7,4742376.59963437,4.74237659963437,72098.7654320988,65.7761137962986
"Warner Hot Springs",8.33333333333333,56,16.8,39.2,421,"Youngs 1994",California,0.92081875395238,33.2838,-116.6308,1603866.66666667,1366773.33333333,6.20516826149317,91.9,14872397.533551,14.872397533551,624228.028503563,23.8252639331239
"Wilbur Hot Spring",1.33333333333333,55.6,12.7,42.9,1107,"Youngs 1994",California,0.1249387366083,39.0387,-122.4208,254387.2,239324.8,5.40549525513195,81.7,2929312.11750306,2.92931211750306,37983.7398373984,77.1201606277561
"Slates Hot Springs",1.58333333333333,47,0,47,,"Youngs 1994",California,0.1995723549052,36.123,-121.6353,245112.666666667,311359.333333333,5.38936575483142,75.3,4134918.10535635,4.13491810535635,#DIV/0!,#DIV/0!
"Menlo Baths Hot Springs",1.58333333333333,56,5.3,50.7,429,"Youngs 1994",California,0.1995723549052,41.2658,-120.082,304734.666666667,335870.6,5.483921862446,32.8,10239957.3170732,10.2399573170732,116391.608391608,87.9784845194343
"Big Alkali Lake Sp.",1.25,57,5.1,51.9,662,"Youngs 1994",California,0.09691001300806,37.67,-118.7815,245810,271437,5.39059954680299,81.8,3318300.73349633,3.31830073349633,59546.8277945619,55.7259027289338
"Keough Hot Springs",33.3333333333333,58,3,55,602,"Youngs 1994",California,1.52287874528034,37.2538,-118.3765,6694400,7670666.66666667,6.82571165851514,81.8,93773431.1328443,93.7734311328443,1746179.40199336,53.7020600665642
"Elgin Mine (Spring)",0.63333333333333,69,12.7,56.3,1107,"Youngs 1994",California,-0.19836765376683,39.057,-122.4708,156342.133333333,149187.493333333,5.19407603373453,81.7,1826040.31007752,1.82604031007752,18042.2764227642,101.208975369293
"Klamath Hot Springs",1.58333333333333,69,10.2,58.8,550,"Youngs 1994",California,0.1995723549052,41.9712,-122.2017,390855.333333333,389530.4,5.59201604240657,66.4,5866421.68674699,5.86642168674699,90785.4545454545,64.6185197410647
"Unnamed Spring",7.88333333333333,65,4.2,60.8,1022,"Youngs 1994",California,0.89670989035417,38.7728,-119.713,1814112.66666667,2005419.09333333,6.25866425570763,65,30852601.4358974,30.8526014358974,243257.142857143,126.831225071225
"Bassett Hot Springs",3.33333333333333,79,9.1,69.9,657,"Youngs 1994",California,0.52287874528034,41.145,-121.1108,962320,974872,5.98331951187681,72.3,13483706.7773167,13.4837067773167,160000,84.2731673582296
"Unnamed Spring",0.06666666666667,84,9.1,74.9,1132,"Youngs 1994",California,-1.17609125905568,41.4088,-122.1948,20641.0666666667,20892.1066666667,4.31473213653451,66.4,314640.16064257,0.31464016064257,1857.24381625442,169.412415262267
"Kellog Hot Spring",0.25,90,8.3,81.7,608,"Youngs 1994",California,-0.60205999132796,41.1275,-121.025,83680,85458.2,4.9226216715232,72.3,1181994.46749654,1.18199446749654,12967.1052631579,91.1533024147511
"Hot Creek Springs",250,88,5.1,82.9,662,"Youngs 1994",California,2.39794000867204,37.6645,-118.8275,81588000,86713400,7.91162628722174,81.8,1060066014.66993,1060.06601466993,11909365.5589124,89.0111240121121
"Terminal Geyser",0.5,96,7.8,88.2,1131,"Youngs 1994",California,-0.30102999566398,40.4213,-121.3767,179912,184514.4,5.2550601314388,87.9,2099139.93174061,2.09913993174061,13941.6445623342,150.566163292658
"Benmac Hot Springs",11.6666666666667,98,5,93,468,"Youngs 1994",California,1.06694678963061,41.5305,-120.0822,4295573.33333333,4539640,6.63302113764,32.8,138403658.536585,138.403658536585,786153.846153846,176.051620447711
"Elwyn Creek",3.93466666666667,25,0,25,716,"Geological Survey of Canada",CANADA,0.59490794610826,57.48,-130.46,246939.68,411566.133333333,5.39259088102316,40.8,10087405.2287582,10.0874052287582,173301.184357542,58.2073646302763
"Crawford Creek",0.227,32,3.2,28.8,820,"Geological Survey of Canada",CANADA,-0.64397414280688,49.4,-116.47,20894.896,27353.3184,4.32004021387455,82.6,331153.975786925,0.33115397578692,8730.08780487805,37.9324908509956
"Wilson Lake",0.52966666666667,30,0.2,29.8,811,"Geological Survey of Canada",CANADA,-0.27599735751228,50.13,-117.36,44322.5066666667,66040.5349333333,4.64662431401092,72.3,913423.719686492,0.91342371968649,20596.261405672,44.3490059528446
"Ram Creek",3.178,34.6,1.7,32.9,689,"Geological Survey of Canada",CANADA,0.50215389287136,50.02,-115.35,327100.0992,437463.1408,5.51468067583396,82.6,5296163.93220339,5.29616393220339,145459.227866473,36.4099549398481
Nascall,0.7945,43.4,5.3,38.1,2480,"Geological Survey of Canada",CANADA,-0.0999060984566,52.28,-127.16,111027.8792,126651.5628,5.04543204421418,70,1809308.04,1.80930804,10102.964516129,179.086844966297
Kidney,1.51333333333333,39,0,39,654,"Geological Survey of Canada",CANADA,0.17993459813744,51.09,-115.34,183621.813333333,246939.68,5.26392427189562,93.5,2641066.09625668,2.64106609625668,72973.2110091743,36.1922691866286
"Weewannie Creek",1.135,47.5,5.6,41.9,2546,"Geological Survey of Canada",CANADA,0.05499586152914,53.42,-128.47,178081.5,198976.396,5.25061880511608,84,2368766.61904762,2.36876661904762,14058.6645718775,168.491580899229
Radium,23.6836666666667,43,0,43,762,"Geological Survey of Canada",CANADA,1.37444894001991,50.38,-116.02,3270051.224,4260975.83733333,6.51455455575701,93.5,45571934.0891266,45.5719340891266,980168.125984252,46.4939971837635
Ainsworth,7.86933333333333,47.5,3.8,43.7,765,"Geological Survey of Canada",CANADA,0.89593794177224,49.44,-116.54,1234698.4,1438835.20213333,6.09156088535918,82.6,17419312.3744956,17.4193123744956,324401.694117647,53.6967367629662
"Taweh Creek",0.3,46,0,46,716,"Geological Survey of Canada",CANADA,-0.52287874528034,57.42,-130.47,45187.2,57739.2,4.65501543134617,40.8,1415176.47058824,1.41517647058824,13213.407821229,107.101550919708
Takhini,3.78333333333333,47,0,47,370,"Geological Survey of Canada",CANADA,0.57787460680948,60.52,-135.22,585690.266666667,743984.933333333,5.76766800673569,74.7,9959637.66175814,9.95963766175814,322462.702702703,30.886169402793
Halcyon,2.497,51,2.9,48.1,849,"Geological Survey of Canada",CANADA,0.39741854235135,50.3,-117.55,428345.368,502522.2488,5.6317940749303,72.3,6950515.197787,6.950515197787,92750.7561837456,74.9375582881238
"Knight Inlet",1.51333333333333,58,5.4,52.6,1246,"Geological Survey of Canada",CANADA,0.17993459813744,51.18,-125.37,303925.76,333051.978666667,5.48276751137225,46.6,7147038.16881259,7.14703816881259,38302.150882825,186.596261674103
"Liard ",72.2616666666667,54,0,54,485,"Geological Survey of Canada",CANADA,1.85890797405721,59.25,-126.05,13303083.7866667,16326511.92,7.12395232640261,92,177462086.086957,177.462086086957,4698647.25773196,37.7687611673615
"South Redstone",20.657,54,0,54,450,"Geological Survey of Canada",CANADA,1.31506724951422,63.24,-125.52,3802871.072,4667159.952,6.58011160185962,76.4,61088481.0471204,61.0884810471204,1447642.56,42.198594276698
"Nahanni North",15.436,58,0,58,583,"Geological Survey of Canada",CANADA,1.18853476989936,62.22,-128.4,3100042.752,3745884.992,6.49136768313416,77.2,48521826.3212435,48.5218263212435,834973.749571184,58.1117985399694
Harrison,26.2563333333333,68,3.9,64.1,1551,"Geological Survey of Canada",CANADA,1.41923407726433,49.2,-121.46,6371676.92266667,7041801.56453333,6.80425374668649,37,190318961.203604,190.318961203604,533861.849129594,356.494777654367
Minnehaha,13.8833333333333,20.4,9.8,10.6,1096,"Bliss 1983","E USA",1.14249375102314,38.1666666666667,-79.9833333333333,604113.813333333,615731.386666667,5.78111876618114,55.9,11014872.7489565,11.0148727489565,399475.182481752,27.5733593274211
Berkeley,103.15,22.2,10.4,11.8,948,"Bliss 1983","E USA",2.01346923230917,39.6333333333333,-78.2333333333333,5265271.12,5092639.28,6.72142073884314,133.5,38147110.7116105,38.1471107116105,3431369.62025316,11.1171674676061
"Warm Spring ES",12.6166666666667,31,17.6,13.4,1252,"Bliss 1983","E USA",1.10094462911643,32.9,-84.6833333333333,1108550.8,707360.986666667,6.04475559970957,28.6,24732901.6317016,24.7329016317016,317794.888178914,77.8266188403175
"Frederick George",1.1,22,6.7,15.3,843,"Bliss 1983","E USA",0.04139268515823,44.7333333333333,-73.2,55228.8,70416.72,4.74216560706507,41.9,1680589.97613365,1.68058997613365,41150.1779359431,40.8404060548599
"Ladies' Pool",11.6666666666667,34.8,11.3,23.5,1011,"Bliss 1983","E USA",1.06694678963061,38,-79.8333333333333,1210570.66666667,1147113.33333333,6.08299014631605,55.9,20520810.9719738,20.5208109719738,363916.913946588,56.3887255182253
"Hot Spring NC",0.53333333333333,39.3,10.3,29,1542,"Bliss 1983","E USA",-0.27300127206374,35.9,-82.8333333333333,65381.9733333333,64712.5333333333,4.81545802414959,36.6,1768102.00364299,1.76810200364299,10907.3929961089,162.101246766641
"HIGHLAND LAND CO. WARM SPRINGS",0.06333333333333,22.7777777777778,10.6,12.1777777777778,270,"Mitchell et al. 1983",Idaho,-1.19836765376683,43.8313,-116.3955,3385.94074074074,3226.94874074074,3.52967935300667,100,32269.4874074074,0.03226948740741,7397.33333333333,4.36231354642314
"KENT WARM SPRINGS",11.97,23.8888888888889,7,16.8888888888889,351,"Mitchell et al. 1983",Idaho,1.07809415040641,42.33991752,-112.43913945,695590,845837.44,5.84235332983436,111.5,7585986.00896861,7.58598600896861,1075458.46153846,7.05372292865382
"THOMAS FLAT WARM SPRINGS",0.06333333333333,23.8888888888889,5.8,18.0888888888889,386,"Mitchell et al. 1983",Idaho,-1.19836765376683,43.1614,-116.3323,3680.37037037037,4793.31437037037,3.56589152566112,145.2,33011.8069584736,0.03301180695847,5174.30051813471,6.37995548244153
"FALL CREEK MINERAL SPRINGS",4.43333333333333,25,4.1,20.9,420,"Mitchell et al. 1983",Idaho,0.64673038624742,43.42325005,-111.41495042,278236,387675.493333333,5.44441332116232,123.3,3144164.58502298,3.14416458502298,332880,9.44533941667562
"WHITTAKER WARM SPRINGS",57,23.3333333333333,1.1,22.2333333333333,356,"Mitchell et al. 1983",Idaho,1.75587485567249,44.6121434,-113.36419979,3179840,5302383.2,6.50240526814001,120.7,43930266.7771334,43.9302667771334,5049303.37078652,8.70026289790754
"TREASURETON WARM SPRINGS #2",0.63333333333333,32.7777777777778,7.7,25.0777777777778,412,"Mitchell et al. 1983",Idaho,-0.19836765376683,42.338561,-111.723972,60358.0740740741,66452.7674074074,4.78073537370881,111.5,595988.945357914,0.59598894535791,48477.6699029126,12.2940922398192
"INDIAN SPRINGS",97.5333333333333,32.2222222222222,6,26.2222222222222,365,"Mitchell et al. 1983",Idaho,1.98915306706963,42.72602284,-112.87388209,9068432.59259259,10700750.4592593,6.9575322291535,103.7,103189493.339048,103.189493339048,8426880,12.2452786012199
"UNNAMED SPRING",0.06333333333333,37.7777777777778,9.5,28.2777777777778,298,"Mitchell et al. 1983",Idaho,-1.19836765376683,44.30528,-116.75141,7360.74074074074,7493.23407407407,3.8669215213251,109.6,68368.9240335226,0.06836892403352,6702.28187919463,10.2008428272399
"NAT-SOO-PAH WARM SPRINGS",1.9,36.1111111111111,6.7,29.4111111111111,292,"Mitchell et al. 1983",Idaho,0.27875360095283,42.3374,-114.5087,207572.888888889,233806.568888889,5.31717062964446,120.6,1938694.60106873,1.93869460106873,205200,9.44782943990609
"ROCKLAND WARM SPRINGS",26.4733333333333,37.7777777777778,6.3,31.4777777777778,357,"Mitchell et al. 1983",Idaho,1.4228086280082,42.54602485,-112.89943478,3076789.62962963,3486618.0082963,6.48809780310013,103.7,33622160.1571485,33.6221601571485,2338551.93277311,14.3773416728353
"REED HOT SPRINGS",0.31666666666667,41.1111111111111,8.7,32.4111111111111,423,"Mitchell et al. 1983",Idaho,-0.49939764943081,43.6966,-115.6607,41220.1481481482,42942.5614814815,4.6151095483313,100,429425.614814815,0.42942561481481,23608.5106382979,18.1894411466261
"JEAN PRESCOTT HOT SPRINGS",28.5,41.1111111111111,7.5,33.6111111111111,294,"Mitchell et al. 1983",Idaho,1.45484486000851,42.76739759,-115.72785982,3709813.33333333,4007923.33333333,6.56935205777062,145.2,27602777.7777778,27.6027777777778,3057061.2244898,9.02918710186595
"MARSH CREEK HOT SPRINGS",0.63333333333333,40,5.8,34.2,358,"Mitchell et al. 1983",Idaho,-0.19836765376683,42.4466,-113.5234,79496,90625.44,4.90034527681205,103.7,873919.382835101,0.8739193828351,55789.9441340782,15.6644606191904
"POOL CREEK HOT SPRINGS",0.12666666666667,42.2222222222222,7.2,35.0222222222222,525,"Mitchell et al. 1983",Idaho,-0.89733765810285,43.7595,-115.5602,17076.9185185185,18560.8438518518,4.232409506216,100,185608.438518518,0.18560843851852,7608.68571428571,24.3942837814984
"KRIGBAUM HOT SPRINGS",3.16666666666667,42.7777777777778,6.9,35.8777777777778,623,"Mitchell et al. 1983",Idaho,0.50060235056919,44.96572716,-116.20401534,434283.703703704,475356.637037037,5.63777353296724,85.2,5579303.25160842,5.57930325160842,160295.345104334,34.8063959560206
"WOLF HOT SPRINGS",3.29333333333333,45,8.4,36.6,341,"Mitchell et al. 1983",Idaho,0.51763568986797,43.3346,-115.044,482275.733333333,504322.624,5.68329541007746,150.8,3344314.48275862,3.34431448275862,304570.557184751,10.9804260584846
"UNNAMED SPRING",82.3333333333333,42.2222222222222,4.5,37.7222222222222,431,"Mitchell et al. 1983",Idaho,1.91557569854,42.89019632,-111.69911895,11099997.037037,12994651.7037037,7.04532286285885,111.5,116543961.468195,116.543961468195,6024278.42227378,19.3457130130793
"RUNNING SPRINGS HOT SPRINGS",4.43333333333333,42.7777777777778,3.3,39.4777777777778,656,"Mitchell et al. 1983",Idaho,0.64673038624742,45.85602681,-114.93955342,607997.185185185,732275.931851852,5.78390156864548,133.8,5472914.28887782,5.47291428887782,213124.390243902,25.6794367017991
"MAGIC HOT SPRINGS",24.3833333333333,45.5555555555556,5.7,39.8555555555556,311,"Mitchell et al. 1983",Idaho,1.38709307574167,42.00713476,-114.50419713,3627373.03703704,4066058.4637037,6.55959222048147,120.6,33715244.3093176,33.7152443093176,2472517.04180064,13.6360007794988
"GOLDBUG (BLM) HOT SPRINGS",11.0833333333333,45,4.3,40.7,289,"Mitchell et al. 1983",Idaho,1.04467039491946,44.904925,-113.92922991,1623043.33333333,1887367.53333333,6.21033011512895,122.8,15369442.4538545,15.3694424538545,1209425.60553633,12.7080511471714
"COLGATE LICKS HOT SPRINGS",3.16666666666667,45,2.5,42.5,694,"Mitchell et al. 1983",Idaho,0.50060235056919,46.46547459,-114.93983861,463726.666666667,563096.666666667,5.66626207077868,63.9,8812154.40792906,8.81215440792906,143896.253602305,61.239637498025
"SALMON HOT SPRINGS",9.18333333333333,45,1.8,43.2,371,"Mitchell et al. 1983",Idaho,0.96300034846814,45.0954786,-113.83700892,1344807.33333333,1659876.48,6.12866006867764,122.8,13516909.4462541,13.5169094462541,780608.086253369,17.315871670162
"BROWN CREEK (OR POOL CREEK) HOT SPRINGS",12.6666666666667,51.1111111111111,7.2,43.9111111111111,525,"Mitchell et al. 1983",Idaho,1.10266234189715,43.77850702,-115.48537409,2178779.25925926,2327171.79259259,6.33821323238404,100,23271717.9259259,23.2717179259259,760868.571428571,30.585726365635
"CONDIE HOT SPRINGS",21.9133333333333,52.2222222222222,7.3,44.9222222222222,310,"Mitchell et al. 1983",Idaho,1.34070844502594,43.33268271,-113.91697341,3871160.77037037,4118711.31437037,6.58784120806265,120.7,34123540.3013287,34.1235403013287,2229222.19354839,15.3073751015426
"GOLD FORK HOT SPRINGS",6.33333333333333,50,4.4,45.6,621,"Mitchell et al. 1983",Idaho,0.80163234623317,44.67545134,-115.94373499,1059946.66666667,1208339.2,6.02528401342035,85.2,14182384.9765258,14.1823849765258,321623.188405797,44.0962762878642
"LOFTUS HOT SPRINGS",2.53333333333333,55,8.7,46.3,423,"Mitchell et al. 1983",Idaho,0.40369233756113,43.72406126,-115.60482156,476976,490755.306666667,5.67849652719569,100,4907553.06666667,4.90755306666667,188868.085106383,25.9840251141552
"UNNAMED SPRING",0.31666666666667,57.2222222222222,9.5,47.7222222222222,298,"Mitchell et al. 1983",Idaho,-0.49939764943081,44.30627626,-116.74682539,62566.2962962963,63228.762962963,4.79634044703939,109.6,576904.771559881,0.57690477155988,33511.4093959732,17.2151748302536
"LOWER LOON CREEK HOT SPRINGS",0.50666666666667,48.8888888888889,0.4,48.4888888888889,547,"Mitchell et al. 1983",Idaho,-0.29527766677489,44.7988,-114.8047,82440.2962962963,102791.272296296,4.91613954399528,133.8,768245.682334053,0.76824568233405,29210.676416819,26.3001674925854
"ELK CREEK HOT SPRINGS",1.26666666666667,53.8888888888889,5,48.8888888888889,398,"Mitchell et al. 1983",Idaho,0.10266234189715,43.42323587,-114.62783448,232599.407407407,259098.074074074,5.3666086039435,150.8,1718156.98988113,1.71815698988113,100365.829145729,17.1189438129028
"SMITH CABIN HOT SPRINGS",44.3333333333333,60,8.7,51.3,423,"Mitchell et al. 1983",Idaho,1.64673038624742,43.72017227,-115.61815527,9274533.33333333,9515671.2,6.96729206644266,100,95156712,95.156712,3305191.4893617,28.7900753424658
"MAPLE GROVE HOT SPRINGS #3",59.2166666666667,60,7.7,52.3,412,"Mitchell et al. 1983",Idaho,1.77244395710568,42.309372,-111.706749,12388126.6666667,12957980.4933333,7.09300563730092,111.5,116215071.689088,116.215071689088,4532662.13592233,25.6394737141466
"PINE FLAT HOT SPRINGS",7.6,59.4444444444444,6.4,53.0444444444444,578,"Mitchell et al. 1983",Idaho,0.88081359228079,44.06073004,-115.68816504,1572254.22222222,1686728.46222222,6.19652276968162,100,16867284.6222222,16.8672846222222,414660.207612457,40.6773650149388
"ROYSTONE HOT SPRINGS",3.16666666666667,63.8888888888889,10.1,53.7888888888889,313,"Mitchell et al. 1983",Idaho,0.50060235056919,43.95294456,-116.35457604,713991.851851852,712666.918518518,5.85369325559134,100,7126669.18518518,7.12666918518518,319054.313099042,22.3368526692598
"SHEEP CREEK HOT SPRINGS",6.33333333333333,57.7777777777778,1.8,55.9777777777778,655,"Mitchell et al. 1983",Idaho,0.80163234623317,45.0353,-115.5606,1266047.40740741,1483336.47407407,6.10244996823265,85.2,17410052.5126065,17.4100525126065,304928.244274809,57.0955719566473
"WARDROP HOT SPRINGS OR HOT SPRING RANCH",12.2233333333333,65,8.4,56.6,341,"Mitchell et al. 1983",Idaho,1.08718965524094,43.38295502,-114.93228869,2812833.46666667,2894661.34933333,6.4491440205944,150.8,19195367.0380194,19.1953670380194,1130425.3372434,16.9806588773287
"LIGHTFOOT HOT SPRINGS",3.16666666666667,62.2222222222222,4.8,57.4222222222222,461,"Mitchell et al. 1983",Idaho,0.50060235056919,43.60823327,-114.95118113,691909.62962963,760806.162962963,5.8400493749248,150.8,5045133.70665095,5.04513370665095,216624.728850325,23.289740434652
"CLEVELAND HOT SPRINGS #1",0.31666666666667,66.1111111111111,7.7,58.4111111111111,412,"Mitchell et al. 1983",Idaho,-0.49939764943081,42.3329,-111.7147,74343.4814814815,77390.8281481481,4.87124289510774,111.5,694088.144826441,0.69408814482644,24238.8349514563,28.6353756777711
"BARTH HOT SPRINGS",12.6666666666667,59.4444444444444,0.6,58.8444444444444,659,"Mitchell et al. 1983",Idaho,1.10266234189715,45.51241325,-115.04344269,2620423.7037037,3118598.63703704,6.41837151929797,133.8,23307912.0854786,23.3079120854786,606154.779969651,38.4520799896119
"VAUGHN HOT SPRING",6.33333333333333,67.7777777777778,7,60.7777777777778,493,"Mitchell et al. 1983",Idaho,0.80163234623317,43.73850591,-115.58371008,1531034.07407407,1610530.07407407,6.18498485628786,100,16105300.7407407,16.1053007407407,405127.789046653,39.7536312644456
"THOMAS CREEK RANCH HOT SPRINGS",4.30666666666667,62.2222222222222,0.3,61.9222222222222,570,"Mitchell et al. 1983",Idaho,0.6341412589394,44.72102046,-115.01537528,940997.096296296,1115782.30162963,5.97358828329501,133.8,8339180.13176106,8.33918013176106,238272,34.9985736123466
"UPPER LOON CREEK HOT SPRINGS",0.31666666666667,62.7777777777778,0,62.7777777777778,545,"Mitchell et al. 1983",Idaho,-0.49939764943081,44.6447,-114.7389,69927.037037037,83176.3703703704,4.84464512661394,150.8,551567.442774339,0.55156744277434,18323.6697247706,30.1013634855418
"SACAJAWEA HOT SPRINGS",1.9,67.2222222222222,2.8,64.4222222222222,538,"Mitchell et al. 1983",Idaho,0.27875360095283,44.16018274,-115.17814898,454893.777777778,512130.897777778,5.65790999641391,150.8,3396093.48659004,3.39609348659004,111372.49070632,30.4931088911827
"SQUAW HOT (VINCENT) SPRINGS #2",7.53666666666667,72.7777777777778,7,65.7777777777778,428,"Mitchell et al. 1983",Idaho,0.8771793076257,42.119227,-111.928401,1979597.61481481,2074197.85481481,6.29657692186503,111.5,18602671.3436306,18.6026713436306,555318.504672897,33.4991022036773
"DEER HOT SPRINGS",1.9,81.1111111111111,8.2,72.9111111111111,483,"Mitchell et al. 1983",Idaho,0.27875360095283,44.09155945,-116.05151223,565304.888888889,579614.168888889,5.75228274135661,100,5796141.68888889,5.79614168888889,124054.658385093,46.7224831726704
"BATTLE CREEK HOT SPRINGS #4",0.31666666666667,83.8888888888889,7,76.8888888888889,428,"Mitchell et al. 1983",Idaho,-0.49939764943081,42.133748,-111.928379,97897.8518518519,101872.651851852,4.99077316229218,111.5,913656.070420196,0.9136560704202,23332.7102803738,39.1577343326768
"BONNEVILLE HOT SPRINGS",22.99,87.7777777777778,3.5,84.2777777777778,560,"Mitchell et al. 1983",Idaho,1.36153897126928,44.15712548,-115.31537642,7481456.88888889,8106692.92888889,6.87398617770343,100,81066929.2888889,81.0669292888889,1294665.42857143,62.6161226675686
,69.6033333333333,20,2.4,17.6,455,"Montana DEQ 2009",Montana,1.84263003865666,46.72,-113.3,2912203.46666667,5125478.10133333,6.46422171451588,97,52839980.4261168,52.8399804261168,4824199.38461538,10.9531087364727
,8.36,41.6666666666667,0.3,41.3666666666667,658,"Montana DEQ 2009",Montana,0.92220627743902,45.337,-110.69,1107644.26666667,1446933.19466667,6.04440030386742,44.9,32225683.6228656,32.2256836228656,400670.151975684,80.4294591547747
,6.65,48.3333333333333,1.4,46.9333333333333,347,"Montana DEQ 2009",Montana,0.8228216453031,45.46,-113.11,1066571.33333333,1305854.29333333,6.02798990679627,122.8,10633992.616721,10.633992616721,604364.265129683,17.5953365052766
,6.35866666666667,56.1111111111111,0.9,55.2111111111111,548,"Montana DEQ 2009",Montana,0.80336605904217,44.45,-114.98,1226770.49481481,1468872.91294815,6.08876332217415,150.8,9740536.55801159,9.74053655801159,365925.02189781,26.618940971825
,31.6666666666667,65,0,65,687,"Montana DEQ 2009",Montana,1.50060235056919,45.09,-110.77,7287133.33333333,8612066.66666667,6.86255671592265,44.9,191805493.689681,191.805493689681,1453624.45414847,131.949825928073
"GEYSER RANCH SPRINGS",3.15,18,8,10,306,"Garside 1994",Nevada,0.4983105537896,38.675,-114.623333333333,105436.8,131796,5.02299221664076,72.7,1812874.82806052,1.81287482806052,324635.294117647,5.58434298706764
"INDIAN SPRING",97.9166666666667,26.1,15.1,11,163,"Garside 1994",Nevada,1.99085662056013,36.5616666666667,-115.6683,6595901.66666667,4506516.66666667,6.8192741724512,72,62590509.2592593,62.5905092592593,18944171.7791411,3.30394540278483
"UNNAMED SPRING",0.31666666666667,21.1,8.9,12.2,236,"Garside 1994",Nevada,-0.49939764943081,41.4921666666667,-118.319166666667,14706.76,16164.1866666667,4.16751700521506,36.1,447761.403508772,0.44776140350877,42315.2542372881,10.5815600444675
"CEDAR SPRING",0.15,25,11.7,13.3,170,"Garside 1994",Nevada,-0.82390874094432,37.7508333333333,-116.28,9414,8347.08,3.97377419397058,90.1,92642.397336293,0.09264239733629,27825.8823529412,3.32936063486593
"FISH CREEK SPRINGS",252.15,19,5.4,13.6,308,"Garside 1994",Nevada,2.40165897249515,39.2769444444444,-116.038333333333,9494960.4,14347940.16,6.9774931577937,130.2,110199233.179724,110.199233179724,25817540.2597403,4.2683862239025
"UNNAMED SPRING",0.31666666666667,23,9,14,330,"Garside 1994",Nevada,-0.49939764943081,41.7459,-119.7919,17224.1333333333,18549.0666666667,4.23613737873524,32.8,565520.325203252,0.56552032520325,30261.8181818182,18.6875858484612
"THOUSAND SPRINGS (GAMBLE RANCH SPRING)",85.1666666666667,20.6,6.3,14.3,276,"Garside 1994",Nevada,1.93026964975107,41.3698333333333,-114.191666666667,3777175.73333333,5095623.86666667,6.57716719087506,77,66176933.3333333,66.1769333333333,9731217.39130435,6.80047836486193
"SULFUR SPRINGS AREA",1.26166666666667,23.3,8.2,15.1,288,"Garside 1994",Nevada,0.10094462911643,39.835,-116.066166666667,70208.2173333333,79710.0813333333,4.84638794594273,127.8,623709.556598853,0.62370955659885,138152.5,4.51464545772861
"CANE SPRING",0.31666666666667,23.3,7.1,16.2,279,"Garside 1994",Nevada,-0.49939764943081,41.258,-118.936166666667,17621.6133333333,21463.92,4.24604566739549,36.1,594568.421052632,0.59456842105263,35793.5483870968,16.6110499753349
"GLADSTONE CORPORATION WELL",26.8166666666667,33.3,16.5,16.8,163,"Garside 1994",Nevada,1.42840479371539,36.06,-115.148333333333,2614281.74666667,1884975.68,6.41735239060062,58.8,32057409.5238095,32.0574095238095,5188284.66257669,6.17880698702616
"HOT CREEK SPRINGS AREA",100,26.1,8.6,17.5,289,"Garside 1994",Nevada,2,40.3283333333333,-116.071666666667,6736240,7322000,6.82841755189107,127.8,57292644.7574335,57.2926447574335,10912110.7266436,5.25037237915344
"BLUE EAGLE SPRINGS",117.166666666667,29,10.3,18.7,230,"Garside 1994",Nevada,2.06880407463618,38.5630555555556,-115.5275,9314281.33333333,9167213.73333333,6.96914935144823,130.2,70408707.6292883,70.4087076292883,16065078.2608696,4.38271799775703
"SCHOOLHOUSE SPRING",288.666666666667,26,5.6,20.4,320,"Garside 1994",Nevada,2.46039663729768,39.4537,-114.7559,19324501.3333333,24638739.2,7.28610829581283,69.8,352990532.951289,352.990532951289,28448100,12.4082287727929
"ELY WARM SPRINGS",1.38333333333333,29,7.1,21.9,277,"Garside 1994",Nevada,0.14092684199243,39.2683333333333,-114.866666666667,109969.466666667,126754.28,5.04127211880448,72.7,1743525.17193948,1.74352517193948,157490.252707581,11.0706862295583
"MCGILL WARM SPRINGS",283.9,29,5.6,23.4,320,"Garside 1994",Nevada,2.45316539252586,39.415,-114.78,22568914.4,27795399.84,7.3535106693379,69.8,398214897.421203,398.214897421203,27978345,14.2329682982036
spring,0.06666666666667,34,9.3,24.7,206,"Garside 1994",Nevada,-1.17609125905568,39.4234,-119.1997,6694.4,6889.65333333333,3.82571165851514,53,129993.459119497,0.1299934591195,10205.8252427184,12.7371825431014
"CARLOTTI RANCH SPRING, SULFUR SPRING",6.30833333333333,39,8.6,30.4,289,"Garside 1994",Nevada,0.79991463345245,40.29,-116.05,765427.933333333,802379.626666667,5.88390430721062,127.8,6278400.83463745,6.27840083463745,688372.318339101,9.12064687578654
"ALKALI HOT SPRINGS",1.58333333333333,50.5,10.2,40.3,157,"Garside 1994",Nevada,0.1995723549052,37.8266666666667,-117.34,268299,266974.066666667,5.42861905397909,50.4,5297104.4973545,5.2971044973545,318038.21656051,16.6555596828618
"POTT'S RANCH HOT SPRING",2.08333333333333,45,3.6,41.4,341,"Garside 1994",Nevada,0.31875876262441,39.0783333333333,-116.64,305083.333333333,360870,5.48441848283391,130.2,2771658.98617512,2.77165898617512,192668.62170088,14.3856273102848
"SOLDIERS MEADOW AREA - UNNAMED HOT SPRING",0.83333333333333,54,6.9,47.1,294,"Garside 1994",Nevada,-0.07918124604762,41.3596666666667,-119.218,153413.333333333,164222,5.18586310629778,36.1,4549085.87257618,4.54908587257618,89387.7551020408,50.8915999443454
"THE HOT SPRINGS",3.78333333333333,57.2,9.4,47.8,224,"Garside 1994",Nevada,0.57787460680948,41.4208333333333,-117.386666666667,747150.826666667,756648.506666667,5.87340828130279,113.8,6648932.3960164,6.6489323960164,532639.285714286,12.4829928515317
"HOT CREEK RANCH SPRING",48.1333333333333,62.8,9.6,53.2,190,"Garside 1994",Nevada,1.68244593851396,38.52,-116.36,10633384.96,10713940.9066667,7.02667153690699,130.2,82288332.6164875,82.2883326164875,7989120,10.3000496445776
"BUFFALO VALLEY HOT SPRINGS",0.12666666666667,65.5,10.6,54.9,210,"Garside 1994",Nevada,-0.89733765810285,40.367,-117.3255,29413.52,29095.536,4.46854700087904,347,83848.8069164265,0.08384880691643,19021.7142857143,4.40805732106905
"BRUFFEY'S HOT SPRINGS",3.15,65.5,6.8,58.7,349,"Garside 1994",Nevada,0.4983105537896,40.2192,-116.068333333333,731467.8,773642.52,5.86419521277149,127.8,6053540.84507042,6.05354084507042,284637.249283668,21.2675637510729
"WALTI HOT SPRINGS",5,72,7.4,64.6,317,"Garside 1994",Nevada,0.69897000433602,39.9016666666667,-116.587,1297040,1351432,6.11295336969349,127.8,10574585.2895149,10.5745852895149,497413.249211356,21.2591548501789
"SAN EMIDIO DESERT - UNNAMED HOT SPRING",0.5,79,11.6,67.4,219,"Garside 1994",Nevada,-0.30102999566398,40.3916666666667,-119.406666666667,144348,141000.8,5.15941077093249,58.9,2393901.52801358,2.39390152801358,72000,33.248632333522
"UNNAMED HOT SPRING",1.66666666666667,85,8.9,76.1,235,"Garside 1994",Nevada,0.22184874961636,40.7616666666667,-117.492166666667,523000,530670.666666667,5.71850168886727,113.8,4663186.87756298,4.66318687756298,223659.574468085,20.8494847075209
"LEE HOT SPRINGS",2.13333333333333,88,8.6,79.4,170,"Garside 1994",Nevada,0.32905871926422,39.2091666666667,-118.723166666667,696217.6,708713.813333333,5.84274499781392,54.7,12956376.8433882,12.9563768433882,395745.882352941,32.7391324108161
"ELLISON RANCH SPRING",0.06333333333333,93,6.5,86.5,327,"Garside 1994",Nevada,-1.19836765376683,41.4666666666667,-116.153333333333,21993.8933333333,22921.3466666667,4.34230211446846,85.7,267460.287825749,0.26746028782575,6107.88990825688,43.7893105218196
"WABUSKA HOT SPRINGS - MAGMA POWER CO. NO. CB 1 WEL",95.5166666666667,97.2,8.3,88.9,285,"Garside 1994",Nevada,1.98007915807411,39.1616666666667,-119.176666666667,34848759.1466667,35528150.0933333,7.54218731886589,54.7,649509142.474101,649.509142474101,10569170.5263158,61.45318034721
"Hughet Spring",250,20,7,13,281,"Black 1994",Oregon,2.39794000867204,43.252,-119.258,10460000,13598000,7.01953168453126,47.9,283883089.770355,283.883089770355,28056939.5017794,10.1181060661428
"Water Tank Spring",5.83333333333333,21,7,14,284,"Black 1994",Oregon,0.76591679396663,43.241,-119.016,268473.333333333,341693.333333333,5.42890115498408,47.9,7133472.51217815,7.13347251217815,647746.478873239,11.0127538239758
"Roadland Spring",30,22,7.7,14.3,258,"Black 1994",Oregon,1.47712125471966,43.500,-119.092,1506240,1794936,6.1778941766265,142.9,12560783.7648705,12.5607837648705,3666976.74418605,3.42537862689899
"Johnson Spring",56.6666666666667,22,6.8,15.2,280,"Black 1994",Oregon,1.75332766665861,43.265,-119.276,2845120,3603818.66666667,6.45410058856545,47.9,75236297.8427279,75.2362978427279,6382285.71428571,11.7882998679178
"Antone Springs",1.66666666666667,23,6.9,16.1,430,"Black 1994",Oregon,0.22184874961636,42.311,-120.399,90653.3333333333,112270.666666667,4.95738377778241,80.1,1401631.29421556,1.40163129421556,122232.558139535,11.4669226885977
"Barnyard Spring",158.333333333333,23,6.8,16.2,280,"Black 1994",Oregon,2.1995723549052,43.281,-119.311,8612066.66666667,10731960,6.93510738307126,47.9,224049269.311065,224.049269311065,17832857.1428571,12.5638459118598
"Upper Dry Creek #1",,23.5,6.6,16.9,944,"Black 1994",Oregon,#NUM!,44.801,-121.29,,0,#NUM!,38.6,0,0,0,#DIV/0!
[...]
394225109482500,0.01833333333333,20,8,12,273,"Blackett and Wakefield 2002",Utah,-1.73675856522542,39.707,-109.807,767.066666666667,920.48,2.8848331106338,65.4,14074.6177370031,0.014074617737,2117.8021978022,6.64586038847695
394719113112200,0.03166666666667,22,9.8,12.2,203,"Blackett and Wakefield 2002",Utah,-1.49939764943081,39.7886,-113.1894,1589.92,1616.41866666667,3.20137527247603,65.7,24603.0238457636,0.02460302384576,4919.40886699507,5.00121549376152
402729111555300,1.9,21,8.8,12.2,413,"Blackett and Wakefield 2002",Utah,0.27875360095283,40.4581,-111.9314,87445.6,96985.12,4.94173796197027,77.9,1244995.12195122,1.24499512195122,145080.871670702,8.58138710923278
402325112252500,28.3883333333333,21.7,9.5,12.2,253,"Blackett and Wakefield 2002",Utah,1.45313989603471,40.3903,-112.4236,1389688.404,1449076.79733333,6.14291743364009,77.9,18601756.063329,18.601756063329,3538555.256917,5.25687878604333
392236110262300,0.00666666666667,21,8.7,12.3,216,"Blackett and Wakefield 2002",Utah,-2.17609125905568,39.3767,-110.4397,306.826666666667,343.088,2.48689310196176,93.4,3673.31905781585,0.00367331905782,973.333333333333,3.77395793611217
381332110441800,6.23,23,10.7,12.3,205,"Blackett and Wakefield 2002",Utah,0.79448804665917,38.2256,-110.7383,338862.16,320615.736,5.53002307482522,166.4,1926777.25961538,1.92677725961538,958386.731707317,2.01043816224681
380219110500500,0.28333333333333,23,10.6,12.4,211,"Blackett and Wakefield 2002",Utah,-0.54770232900537,38.0386,-110.8347,15411.0666666667,14699.7866666667,4.18783269916069,166.4,88340.0641025641,0.08834006410256,42346.9194312796,2.08610367150607
413841112172900,0.63333333333333,22,9.5,12.5,358,"Blackett and Wakefield 2002",Utah,-0.19836765376683,41.6447,-112.2914,31798.4,33123.3333333333,4.50240526814001,145.4,227808.344795965,0.22780834479597,55789.9441340782,4.08332269070714
403354112443000,113.566666666667,22.7,10.2,12.5,222,"Blackett and Wakefield 2002",Utah,2.05525087884822,40.565,-112.7417,6034569.25333333,5939536.66666667,6.78064627566339,65.7,90403906.6463724,90.4039066463724,16132605.4054054,5.6038007733135
392555113523000,63.0833333333333,20,7.3,12.7,321,"Blackett and Wakefield 2002",Utah,1.79991463345245,39.432,-113.875,2639406.66666667,3352046.46666667,6.42150630931167,65.7,51020494.1653983,51.0204941653983,6197495.3271028,8.2324376982224
404359112372400,1.58333333333333,22.2,9.4,12.8,277,"Blackett and Wakefield 2002",Utah,0.1995723549052,40.733,-112.6233,80820.9333333333,84795.7333333333,4.90752386143917,145.4,583189.362677671,0.58318936267767,180259.927797834,3.23526903512206
404436111381800,1.9,22.2,9.3,12.9,420,"Blackett and Wakefield 2002",Utah,0.27875360095283,40.7433,-111.6383,96985.12,102549.84,4.9867051074868,145.4,705294.635488308,0.70529463548831,142662.857142857,4.94378599737458
394603110423000,0.19,20,7,13,290,"Blackett and Wakefield 2002",Utah,-0.72124639904717,39.7675,-110.7083,7949.6,10334.48,3.90034527681205,93.4,110647.537473233,0.11064753747323,20661.5172413793,5.3552474477352
400947111371600,103.466666666667,22.7,9.7,13,358,"Blackett and Wakefield 2002",Utah,2.01480045786649,40.163,-111.621,5497887.57333333,5627758.93333333,6.74019585468166,77.9,72243375.2674369,72.2433752674369,9114315.08379888,7.92636359432568
404149111293600,3.15,21,7.8,13.2,573,"Blackett and Wakefield 2002",Utah,0.4983105537896,40.697,-111.4932,144975.6,173970.72,5.16129491480704,145.4,1196497.38651994,1.19649738651994,173365.445026178,6.90159095048771
411937111493500,21.45,24,10.6,13.4,452,"Blackett and Wakefield 2002",Utah,1.33142729652074,41.3269,-111.8264,1256455.2,1202607.12,6.0991470080582,145.4,8271025.58459422,8.27102558459422,1496564.60176991,5.52667460850838
395403113265700,0.19,22.5,8.8,13.7,227,"Blackett and Wakefield 2002",Utah,-0.72124639904717,39.9008,-113.4492,9937,10890.952,3.9972552898201,65.7,165767.914764079,0.16576791476408,26395.7709251101,6.28009370267663
395314113244700,198.103333333333,23.5,9.3,14.2,215,"Blackett and Wakefield 2002",Utah,2.29689178314124,39.8872,-113.4131,11189668.68,11769873.7226667,7.04881722749546,65.7,179145718.76205,179.14571876205,29057612.6511628,6.16519054447788
403847112312600,25.2333333333333,24.4,10.1,14.3,278,"Blackett and Wakefield 2002",Utah,1.40197462478041,40.6464,-112.5239,1520298.24,1509740.61333333,6.18192879273488,145.4,10383360.4768455,10.3833604768455,2862440.28776978,3.62745050829881
411955112241800,19.55,25,10.6,14.4,339,"Blackett and Wakefield 2002",Utah,1.29114676173189,41.332,-112.405,1226958,1177879.68,6.08882969664678,145.4,8100960.66024759,8.10096066024759,1818669.02654867,4.45433475909631
384626112054500,88.3166666666667,20,5.6,14.4,401,"Blackett and Wakefield 2002",Utah,1.94604266913069,38.7738,-112.0957,3695169.33333333,5321043.84,6.5676343449899,246.2,21612688.2209586,21.6126882209586,6945522.19451371,3.11174417353824
394603110420100,0.05833333333333,22,7,15,290,"Blackett and Wakefield 2002",Utah,-1.23408320603337,39.7675,-110.7003,2928.8,3661,3.46668971587347,93.4,39197.0021413276,0.03919700214133,6343.44827586207,6.17913167046369
413533112160000,0.95,24.5,9.5,15,358,"Blackett and Wakefield 2002",Utah,-0.02227639471115,41.5925,-112.2667,57634.6,59622,4.76068328338304,145.4,410055.020632737,0.41005502063274,83684.9162011173,4.89998722884857
380639110571000,0.56666666666667,25,9.7,15.3,232,"Blackett and Wakefield 2002",Utah,-0.24667233334139,38.1108,-110.9528,35564,36275.28,4.55101060157351,166.4,218000.480769231,0.21800048076923,77027.5862068966,2.83016113452757
380635110564800,0.63333333333333,25,9.7,15.3,232,"Blackett and Wakefield 2002",Utah,-0.19836765376683,38.1097,-110.9467,39748,40542.96,4.59931528114807,166.4,243647.596153846,0.24364759615385,86089.6551724138,2.83016113452757
372000113413000,6.5,29.6,14,15.6,272,"Blackett and Wakefield 2002",Utah,0.81291335664286,37.3333,-113.6917,533041.6,424257.6,5.72676110385855,96.9,4378303.40557276,4.37830340557276,753617.647058823,5.80971454511469
415004112031000,0.63333333333333,25,9.2,15.8,409,"Blackett and Wakefield 2002",Utah,-0.19836765376683,41.8344,-112.0528,39748,41867.8933333333,4.59931528114807,145.4,287949.7478221,0.2879497478221,48833.2518337408,5.89659170768439
401034111480400,28.3166666666667,24,8.1,15.9,435,"Blackett and Wakefield 2002",Utah,1.4520421284854,40.1761,-111.8011,1658677.06666667,1883783.24,6.21976184002286,77.9,24182069.8331194,24.1820698331194,2052860.68965517,11.7796935539651
402348112241200,63.0833333333333,24,8.1,15.9,353,"Blackett and Wakefield 2002",Utah,1.79991463345245,40.3967,-112.4033,3695169.33333333,4196656.6,6.5676343449899,77.9,53872356.8677792,53.8723568677792,5635682.71954674,9.55915361965444
391207111165400,0.01333333333333,21.5,5.1,16.4,333,"Blackett and Wakefield 2002",Utah,-1.8750612633917,39.2019,-111.2817,641.546666666667,914.901333333333,2.80722825282113,166.4,5498.20512820513,0.00549820512821,1262.7027027027,4.35431484896382
413533112161900,0.12666666666667,26,9.5,16.5,358,"Blackett and Wakefield 2002",Utah,-0.89733765810285,41.5925,-112.2719,8479.57333333333,8744.56,3.92837400041229,145.4,60141.4030261348,0.06014140302613,11157.9888268156,5.38998595173342
395100113234100,53.6266666666667,26,9.3,16.7,215,"Blackett and Wakefield 2002",Utah,1.72938080286902,39.85,-113.3947,3589983.57333333,3747045.35466667,6.55509246138417,65.7,57032653.8001015,57.0326538001015,7865909.58139535,7.25061141498455
375607112253000,17.6666666666667,20,3.2,16.8,527,"Blackett and Wakefield 2002",Utah,1.24715461488113,37.9353,-112.425,739173.333333333,1241811.2,5.86874629074034,246.2,5043912.26645004,5.04391226645004,1057184.06072106,4.77108240074088
414925113154500,0.31666666666667,25,8.1,16.9,267,"Blackett and Wakefield 2002",Utah,-0.49939764943081,41.8236,-113.2625,19874,22391.3733333333,4.29828528548408,86.9,257668.277713847,0.25766827771385,37402.2471910112,6.88911220756201
403213113571400,0.63333333333333,23.9,7,16.9,279,"Blackett and Wakefield 2002",Utah,-0.19836765376683,40.537,-113.954,36833.1466666667,44782.7466666667,4.56623882234648,65.7,681624.759005581,0.68162475900558,71587.0967741935,9.52161478423441
395029113233600,340.686666666667,27,9.3,17.7,215,"Blackett and Wakefield 2002",Utah,2.53235513707124,39.8414,-113.3933,24232361.2266667,25230164.336,7.38439573430874,65.7,384020766.149163,384.020766149163,49971603.3488372,7.68477976318722
385804111195100,0.015,20.5,2.7,17.8,459,"Blackett and Wakefield 2002",Utah,-1.82390874094432,38.9678,-111.3308,658.98,1117.128,2.81887223398484,246.2,4537.48172217709,0.00453748172218,1030.58823529412,4.40280760713531
414349112062000,30.8333333333333,27,9.1,17.9,407,"Blackett and Wakefield 2002",Utah,1.48902047801937,41.7303,-112.1056,2193113.33333333,2309219.33333333,6.34106107525686,145.4,15881838.606144,15.881838606144,2389090.90909091,6.64764934047122
375747110300400,0.25,31,12.5,18.5,163,"Blackett and Wakefield 2002",Utah,-0.60205999132796,37.963,-110.5012,21966,19351,4.34175097926517,166.4,116292.067307692,0.11629206730769,48368.0981595092,2.40431341592515
395030113233000,4.73333333333333,27.8,9.3,18.5,215,"Blackett and Wakefield 2002",Utah,0.67516708966339,39.8417,-113.3917,352515.946666667,366378.933333333,5.54717876783151,65.7,5576543.88635211,5.5765438863521,694280.930232558,8.03211444174935
381014110321700,0.28333333333333,27,8.4,18.6,287,"Blackett and Wakefield 2002",Utah,-0.54770232900537,38.1706,-110.5381,20152.9333333333,22049.68,4.30433826823212,166.4,132510.096153846,0.13251009615385,31133.1010452962,4.25624469470788
395002113232600,209.545,28.5,9.3,19.2,215,"Blackett and Wakefield 2002",Utah,2.32127730249596,39.8339,-113.3906,16219621.18,16833336.576,7.21004070675819,65.7,256215168.584475,256.215168584475,30735865.6744186,8.33603228549122
392105113305200,11.1033333333333,28.5,9.2,19.3,236,"Blackett and Wakefield 2002",Utah,1.04545337797151,39.3514,-113.5144,859442.413333333,896607.490666667,5.93421678223375,65.7,13646993.7696601,13.6469937696601,1483706.44067797,9.19790694136517
392527113290900,6.31666666666667,28,8.5,19.5,261,"Blackett and Wakefield 2002",Utah,0.80048795958443,39.4242,-113.4858,475720.8,515364.2,5.67735214054695,65.7,7844203.95738204,7.84420395738204,763227.586206896,10.2776735264069
381608112543200,3.15,28,8.4,19.6,315,"Blackett and Wakefield 2002",Utah,0.4983105537896,38.269,-112.909,237232.8,258320.16,5.37517473475212,90.2,2863859.86696231,2.86385986696231,315360,9.08124006520264
402815114012900,63.09,27,7,20,279,"Blackett and Wakefield 2002",Utah,1.79996052740598,40.4708,-114.0247,4487465.52,5279371.2,6.65200112464348,69.8,75635690.5444126,75.6356905444126,7131205.16129032,10.6062984914498
392046111130700,0.04166666666667,22.5,2.4,20.1,497,"Blackett and Wakefield 2002",Utah,-1.38021124171161,39.3461,-111.2186,2179.16666666667,3504.1,3.33829044715567,93.4,37517.130620985,0.03751713062099,2643.86317907445,14.1902693444669
394926110035300,0.06333333333333,24,3.6,20.4,445,"Blackett and Wakefield 2002",Utah,-1.19836765376683,39.8239,-110.0647,3709.81333333333,5405.728,3.56935205777062,93.4,57877.1734475375,0.05787717344754,4488.26966292135,12.8952085757401
392457110283500,1.89333333333333,29,8.1,20.9,242,"Blackett and Wakefield 2002",Utah,0.27722708099136,39.4158,-110.4764,150512.426666667,165563.669333333,5.1775723578034,93.4,1772630.29264811,1.77263029264811,246727.933884297,7.18455452020029
402956114023900,643.52,29,7,22,279,"Blackett and Wakefield 2002",Utah,2.80856204891665,40.4989,-114.0442,51157265.92,59234728.96,7.70890732572869,69.8,848635085.386819,848.635085386819,72738518.7096774,11.6669283405948
392758114021000,504.721666666667,26.8,4.3,22.5,453,"Blackett and Wakefield 2002",Utah,2.70305194850583,39.4661,-114.0361,35477491.616,47514497.7,7.54995290609091,69.8,680723462.750716,680.723462750716,35136650.0662252,19.3736016799466
383528112063800,0.63166666666667,25,1.8,23.2,564,"Blackett and Wakefield 2002",Utah,-0.19951204041557,38.5911,-112.1106,39643.4,61315.1253333333,4.59817089449933,246.2,249046.000541565,0.24904600054157,35319.5744680851,7.05121747054467
402756109131600,170.343333333333,31,7.8,23.2,214,"Blackett and Wakefield 2002",Utah,2.23132514140726,40.4656,-109.2211,14967046.64,16535022.9546667,7.1751361120004,65.4,252829097.166157,252.829097166157,25102557.7570093,10.0718460490569
401036111480300,20.8833333333333,32,8.1,23.9,435,"Blackett and Wakefield 2002",Utah,1.31979982061051,40.1767,-111.8008,1922269.06666667,2088283.21333333,6.28381417729193,77.9,26807229.9529311,26.8072299529311,1513969.65517241,17.7065833924381
401035111480600,21.64,32,8.1,23.9,435,"Blackett and Wakefield 2002",Utah,1.33525725643453,40.1764,-111.8017,1991918.72,2163948.064,6.29927161311596,77.9,27778537.406932,27.778537406932,1568825.37931034,17.7065833924381
385147112302500,2.2,35,8.1,26.9,319,"Blackett and Wakefield 2002",Utah,0.34242268082221,38.863,-112.507,230120,247609.12,5.36195436535346,246.2,1005723.47684809,1.00572347684809,217489.655172414,4.62423592538601
383538112323500,1.26166666666667,33.9,6.3,27.6,393,"Blackett and Wakefield 2002",Utah,0.10094462911643,38.5939,-112.5431,126163.638666667,145695.248,5.10093420592378,246.2,591775.987002437,0.59177598700244,101241.526717557,5.8451902711164
400812111494300,8.45333333333333,36.5,8.1,28.4,435,"Blackett and Wakefield 2002",Utah,0.92702799449003,40.1367,-111.8286,937271.786666667,1004472.40533333,5.97186554428606,77.9,12894382.610184,12.894382610184,612837.517241379,21.0404589265792
403130111280000,3.15,39,10,29,413,"Blackett and Wakefield 2002",Utah,0.4983105537896,40.525,-111.4667,382208.4,382208.4,5.58230022754777,77.9,4906397.94608472,4.90639794608472,240528.813559322,20.3983791940779
403133111291000,9.46666666666667,39.8,10,29.8,413,"Blackett and Wakefield 2002",Utah,0.97619708532738,40.5258,-111.4861,1180334.29333333,1180334.29333333,6.07200502526285,77.9,15151916.4741121,15.1519164741121,722859.079903148,20.9610931028801
404729111540100,4,42,8.7,33.3,532,"Blackett and Wakefield 2002",Utah,0.60205999132796,40.7914,-111.9003,535552,557308.8,5.72880164550709,145.4,3832935.35075653,3.83293535075653,237112.781954887,16.1650304937411
402056111541900,11.9833333333333,44,8.8,35.2,379,"Blackett and Wakefield 2002",Utah,1.07857763999924,40.3489,-111.9053,1704701.06666667,1764866.98666667,6.23164823290071,77.9,22655545.4000856,22.6555454000856,997114.511873351,22.7211068842243
414120113590000,14.2,42,6.6,35.4,271,"Blackett and Wakefield 2002",Utah,1.15228834438306,41.6889,-113.9833,1901209.6,2103213.12,6.27902999856218,77,27314456.1038961,27.3144561038961,1652439.85239852,16.5297732708692
403207111285800,5.67833333333333,45.5,10,35.5,413,"Blackett and Wakefield 2002",Utah,0.75422088318423,40.5353,-111.4828,843414.206666667,843414.206666667,5.92604091209855,77.9,10826883.2691485,10.8268832691485,433588.18401937,24.9704297030954
402103111540400,1.57666666666667,44.5,8.8,35.7,379,"Blackett and Wakefield 2002",Utah,0.19773988601815,40.3508,-111.9011,227588.68,235504.808,5.35715065695064,77.9,3023168.26700899,3.02316826700899,131191.978891821,23.0438498797389
400214111314200,1.33333333333333,42,5.7,36.3,498,"Blackett and Wakefield 2002",Utah,0.1249387366083,40.0372,-111.5283,178517.333333333,202505.6,5.25168039078742,77.9,2599558.40821566,2.59955840821566,84433.734939759,30.7881489557506
413437112135700,1.57666666666667,47,9.7,37.3,407,"Blackett and Wakefield 2002",Utah,0.19773988601815,41.5769,-112.2325,244080.613333333,246059.645333333,5.38753328594436,145.4,1692294.67216873,1.69229467216873,122166.486486486,13.8523642681328
415118112092600,100.833333333333,53,9,44,378,"Blackett and Wakefield 2002",Utah,2.00360412426883,41.855,-112.1572,18141126.6666667,18563013.3333333,7.25866425570763,145.4,127668592.388812,127.668592388812,8412380.95238095,15.1762732942662
413936112051100,60,54,9.1,44.9,407,"Blackett and Wakefield 2002",Utah,1.77815125038364,41.66,-112.0864,11045760,11271696,7.04319560272905,145.4,77521980.7427785,77.5219807427785,4649041.76904177,16.6748299098971
412015112014000,2.01666666666667,58,10.7,47.3,412,"Blackett and Wakefield 2002",Utah,0.30463411993281,41.3375,-112.0278,405011.2,399104.786666667,5.60746703316761,145.4,2744874.73635947,2.74487473635947,154363.106796116,17.7819350318267
404857111550500,14.5,56,8.5,47.5,522,"Blackett and Wakefield 2002",Utah,1.16136800223497,40.8158,-111.9181,2790728,2881730,6.44571750977577,145.4,19819325.997249,19.819325997249,876000,22.6248013667226
383651112120400,2.01666666666667,63,1.8,61.2,564,"Blackett and Wakefield 2002",Utah,0.30463411993281,38.6142,-112.201,447199.866666667,516389.28,5.65050166539281,246.2,2097438.18034119,2.09743818034119,112761.70212766,18.6006253964368
383759112062500,9.01666666666667,70,1.8,68.2,564,"Blackett and Wakefield 2002",Utah,0.95504601472293,38.633,-112.107,2263544,2572895.01333333,6.35478894096579,246.2,10450426.536691,10.450426536691,504165.957446809,20.7281479091011
393645112434100,20,84,9.8,74.2,202,"Blackett and Wakefield 2002",Utah,1.30102999566398,39.6125,-112.7281,6192320,6209056,6.79185339125418,65.7,94506179.6042618,94.5061796042618,3122376.23762376,30.2673900939575
383816112055700,9.01666666666667,76.5,1.8,74.7,564,"Blackett and Wakefield 2002",Utah,0.95504601472293,38.6378,-112.0992,2508761.26666667,2818112.28,6.39945933588525,246.2,11446434.9309504,11.4464349309504,504165.957446809,22.7037045280037
381107113114900,15.1666666666667,89.5,9.8,79.7,271,"Blackett and Wakefield 2002",Utah,1.18089014193745,38.1853,-113.1969,5044858,5057549.46666667,6.70284894645314,90.2,56070393.2002956,56.0703932002956,1764929.88929889,31.7691901192569
"Emmett Lynch warm spring",3.15,22.2,11.3,10.9,277,"Schuster and Bloomquist 1994",Washington,0.4983105537896,46.020485,-118.769882,160791.12,143657.64,5.20626206032357,64.6,2223802.47678019,2.22380247678019,358622.38267148,6.20095840146521
"Clerf Spring",69.4,20,8.2,11.8,277,"Schuster and Bloomquist 1994",Washington,1.84135947045486,46.999113,-120.371522,2903696,3426361.28,6.46295114631407,288.5,11876468.9081456,11.8764689081456,7901077.25631769,1.50314552343469
"Orr Creek Warm Springs",1.66666666666667,22,7.1,14.9,2328,"Schuster and Bloomquist 1994",Washington,0.22184874961636,46.343819,-121.608819,83680,103902.666666667,4.9226216715232,46.2,2248975.46897547,2.24897546897547,22577.3195876289,99.6121554751692
"Longmire Springs",0.03333333333333,22,6.8,15.2,2371,"Schuster and Bloomquist 1994",Washington,-1.47712125471966,46.751819,-121.813088,1673.6,2119.89333333333,3.22365166718718,46.2,45885.1370851371,0.04588513708514,443.357233234922,103.494729860027
"Garland Mineral Springs",1.66666666666667,29,5.9,23.1,2293,"Schuster and Bloomquist 1994",Washington,0.22184874961636,47.88983,-121.342252,132493.333333333,161084,5.1221940264284,36.2,4449834.25414365,4.44983425414365,22921.9363279546,194.129945676396
"Bonneville Hot Springs",1.33333333333333,36.3,10.3,26,1925,"Schuster and Bloomquist 1994",Washington,0.1249387366083,45.656324,-121.957691,146718.933333333,145045.333333333,5.16648616095728,38.6,3757651.12262521,3.75765112262521,21843.1168831169,172.02907180017
"Shiperds Hot Springs",1.66666666666667,42,8.8,33.2,2222,"Schuster and Bloomquist 1994",Washington,0.22184874961636,45.739125,-121.805487,223146.666666667,231514.666666667,5.34859040379548,38.6,5997789.29188256,5.99778929188256,23654.3654365437,253.559509257288
"Ohanapecosh Hot Springs(USGS)",1.83333333333333,50,6,44,2167,"Schuster and Bloomquist 1994",Washington,0.26324143477458,46.737157,-121.561402,306826.666666667,337509.333333333,5.48689310196176,46.2,7305396.82539682,7.30539682539682,26680.2030456853,273.813389384166
"Lester Hot Springs",0.31666666666667,46.5,0.8,45.7,2685,"Schuster and Bloomquist 1994",Washington,-0.49939764943081,47.207053,-121.547417,48360.0666666667,60549.4533333333,4.68448689088488,46.2,1310594.22799423,1.31059422799423,3719.32960893855,352.373778555285
,,,,,,,,,,,,,,,,,,
,,,,,,,,,,,,,,91.7324510932104,,,,
,,,,,,,,,,,,,,45.4410045048945,,,,